Starting training...
Traceback (most recent call last):                                                                                                                                                   
  File "C:\Users\nicla\Desktop\UNI\Informatik\PL_MAI\Project-Lab-MAI\train_intra_loss.py", line 235, in <module>
    main()
  File "C:\Users\nicla\Desktop\UNI\Informatik\PL_MAI\Project-Lab-MAI\train_intra_loss.py", line 171, in main
    train_metrics = train_epoch(model, train_loader, optimizer, device)
                    ^^^^^^^^^^^^^^^^^^^^^^^^^^^^^^^^^^^^^^^^^^^^^^^^^^^
  File "C:\Users\nicla\Desktop\UNI\Informatik\PL_MAI\Project-Lab-MAI\train_intra_loss.py", line 50, in train_epoch
    for batch in progress_bar:
                 ^^^^^^^^^^^^
  File "C:\Users\nicla\anaconda3\envs\PL_MAI\Lib\site-packages\tqdm\std.py", line 1181, in __iter__
    for obj in iterable:
               ^^^^^^^^
  File "C:\Users\nicla\anaconda3\envs\PL_MAI\Lib\site-packages\torch\utils\data\dataloader.py", line 701, in __next__
    data = self._next_data()
           ^^^^^^^^^^^^^^^^^
  File "C:\Users\nicla\anaconda3\envs\PL_MAI\Lib\site-packages\torch\utils\data\dataloader.py", line 1465, in _next_data
    return self._process_data(data)
           ^^^^^^^^^^^^^^^^^^^^^^^^
  File "C:\Users\nicla\anaconda3\envs\PL_MAI\Lib\site-packages\torch\utils\data\dataloader.py", line 1491, in _process_data
    data.reraise()
  File "C:\Users\nicla\anaconda3\envs\PL_MAI\Lib\site-packages\torch\_utils.py", line 715, in reraise
    raise exception
RuntimeError: Caught RuntimeError in DataLoader worker process 0.
Original Traceback (most recent call last):
  File "C:\Users\nicla\anaconda3\envs\PL_MAI\Lib\site-packages\torch\utils\data\_utils\worker.py", line 351, in _worker_loop
    data = fetcher.fetch(index)  # type: ignore[possibly-undefined]
           ^^^^^^^^^^^^^^^^^^^^
  File "C:\Users\nicla\anaconda3\envs\PL_MAI\Lib\site-packages\torch\utils\data\_utils\fetch.py", line 55, in fetch
    return self.collate_fn(data)
           ^^^^^^^^^^^^^^^^^^^^^
  File "C:\Users\nicla\anaconda3\envs\PL_MAI\Lib\site-packages\torch\utils\data\_utils\collate.py", line 398, in default_collate
    return collate(batch, collate_fn_map=default_collate_fn_map)
           ^^^^^^^^^^^^^^^^^^^^^^^^^^^^^^^^^^^^^^^^^^^^^^^^^^^^^
  File "C:\Users\nicla\anaconda3\envs\PL_MAI\Lib\site-packages\torch\utils\data\_utils\collate.py", line 172, in collate
    key: collate(
         ^^^^^^^^
  File "C:\Users\nicla\anaconda3\envs\PL_MAI\Lib\site-packages\torch\utils\data\_utils\collate.py", line 155, in collate
    return collate_fn_map[elem_type](batch, collate_fn_map=collate_fn_map)
           ^^^^^^^^^^^^^^^^^^^^^^^^^^^^^^^^^^^^^^^^^^^^^^^^^^^^^^^^^^^^^^^
  File "C:\Users\nicla\anaconda3\envs\PL_MAI\Lib\site-packages\torch\utils\data\_utils\collate.py", line 272, in collate_tensor_fn
    return torch.stack(batch, 0, out=out)
           ^^^^^^^^^^^^^^^^^^^^^^^^^^^^^^
RuntimeError: stack expects each tensor to be equal size, but got [147, 3, 112, 112] at entry 0 and [363, 3, 112, 112] at entry 1
