Starting training...
Traceback (most recent call last):                                                                                                       
  File "C:\Users\nicla\Desktop\UNI\Informatik\PL_MAI\Project-Lab-MAI\train_intra_loss.py", line 231, in <module>
    main()
  File "C:\Users\nicla\Desktop\UNI\Informatik\PL_MAI\Project-Lab-MAI\train_intra_loss.py", line 167, in main
    train_metrics = train_epoch(model, train_loader, optimizer, device)
                    ^^^^^^^^^^^^^^^^^^^^^^^^^^^^^^^^^^^^^^^^^^^^^^^^^^^
  File "C:\Users\nicla\Desktop\UNI\Informatik\PL_MAI\Project-Lab-MAI\train_intra_loss.py", line 50, in train_epoch
    for batch in progress_bar:
                 ^^^^^^^^^^^^
  File "C:\Users\nicla\anaconda3\envs\PL_MAI\Lib\site-packages\tqdm\std.py", line 1181, in __iter__
    for obj in iterable:
               ^^^^^^^^
  File "C:\Users\nicla\anaconda3\envs\PL_MAI\Lib\site-packages\torch\utils\data\dataloader.py", line 701, in __next__
    data = self._next_data()
           ^^^^^^^^^^^^^^^^^
  File "C:\Users\nicla\anaconda3\envs\PL_MAI\Lib\site-packages\torch\utils\data\dataloader.py", line 1465, in _next_data
    return self._process_data(data)
           ^^^^^^^^^^^^^^^^^^^^^^^^
  File "C:\Users\nicla\anaconda3\envs\PL_MAI\Lib\site-packages\torch\utils\data\dataloader.py", line 1491, in _process_data
    data.reraise()
  File "C:\Users\nicla\anaconda3\envs\PL_MAI\Lib\site-packages\torch\_utils.py", line 715, in reraise
    raise exception
TypeError: Caught TypeError in DataLoader worker process 0.
Original Traceback (most recent call last):
  File "C:\Users\nicla\anaconda3\envs\PL_MAI\Lib\site-packages\PIL\Image.py", line 3098, in fromarray
    mode, rawmode = _fromarray_typemap[typekey]
                    ~~~~~~~~~~~~~~~~~~^^^^^^^^^
KeyError: ((1, 1, 224), '|u1')

The above exception was the direct cause of the following exception:

Traceback (most recent call last):
  File "C:\Users\nicla\anaconda3\envs\PL_MAI\Lib\site-packages\torch\utils\data\_utils\worker.py", line 351, in _worker_loop
    data = fetcher.fetch(index)  # type: ignore[possibly-undefined]
           ^^^^^^^^^^^^^^^^^^^^
  File "C:\Users\nicla\anaconda3\envs\PL_MAI\Lib\site-packages\torch\utils\data\_utils\fetch.py", line 52, in fetch
    data = [self.dataset[idx] for idx in possibly_batched_index]
            ~~~~~~~~~~~~^^^^^
  File "C:\Users\nicla\Desktop\UNI\Informatik\PL_MAI\Project-Lab-MAI\data_loader\vox_celeb2\VoxCeleb2Ada.py", line 249, in __getitem__
    aligned_faces = self._get_aligned_face(video)
                    ^^^^^^^^^^^^^^^^^^^^^^^^^^^^^
  File "C:\Users\nicla\Desktop\UNI\Informatik\PL_MAI\Project-Lab-MAI\data_loader\vox_celeb2\VoxCeleb2Ada.py", line 225, in _get_aligned_face
    frame = PIL.Image.fromarray(frame.numpy())
            ^^^^^^^^^^^^^^^^^^^^^^^^^^^^^^^^^^
  File "C:\Users\nicla\anaconda3\envs\PL_MAI\Lib\site-packages\PIL\Image.py", line 3102, in fromarray
    raise TypeError(msg) from e
TypeError: Cannot handle this data type: (1, 1, 224), |u1
